Workbook

Sheet README
A1: Whitfield Farms LLC
A2: AcreFlow test account SAM - Profitable with periodic cash-flow squeeze
A3: Fictional business. All names, customers, vendors and lenders are invented; market prices approximate public 2023-2026 data.
A5: Owner: Sam Whitfield ("Farmer Sam"); spouse Megan Whitfield
A6: Location: McPherson County (near Canton), Kansas + Carson County (near Panhandle), Texas
A7: Years Operating: 18
A8: Total Acres: 400
A9: Business Structure: Multi-member LLC taxed as partnership (Sam & Megan)
A10: Primary Activities: KS corn/soybean/wheat rotation (125 ac pivot-irrigated, 160 ac dryland); TX dryland cotton (96 planted ac, fully custom-farmed); custom combining & grain hauling for neighbors
A11: Employees Full Time: 0
A12: Employees Seasonal: 1 seasonal hand/CDL truck driver (May-Nov)
A13: Family Labor: Sam full-time (operates combine on custom jobs); Megan runs grain cart at harvest and keeps books (unpaid)
... A35: Seasonality: Dec prepay; Mar-May inputs/planting; Jun-Jul wheat harvest + custom wheat run; Sep-Nov fall harvest + custom corn/soy; Nov-Dec cotton stripping & ginning; Jan-Oct pool payments.

Sheet Checks
A1: Integrity checks - live formulas tying statements to the ledger and sub-ledgers (all differences should be 0)
A3: Check | B3: Year | C3: Ledger value (formula) | D3: Statement value | E3: Difference
A4: Revenue: ledger (section REV) vs IS_Annual TOTAL | B4: 2023 | C4: =SUMIFS(Transactions!$Q$2:$Q$1092,Transactions!$J$2:$J$1092,"REV",Transactions!$AA$2:$AA$1092,2023,Transactions!$F$2:$F$1092,"Current",Transactions!$C$2:$C$1092,"<="&DATE(2026,9,30)) -> 374668.55 | D4: =IS_Annual_Enterprise!D27 -> 374668.55 | E4: =ROUND(C4-D4,2) -> 0
A5: Cost of production: ledger (section COP) vs IS_Annual TOTAL | B5: 2023 | C5: =SUMIFS(Transactions!$Q$2:$Q$1092,Transactions!$J$2:$J$1092,"COP",Transactions!$AA$2:$AA$1092,2023,Transactions!$F$2:$F$1092,"Current",Transactions!$C$2:$C$1092,"<="&DATE(2026,9,30)) -> 233214.89 | D5: =IS_Annual_Enterprise!F27 -> 233214.89 | E5: =ROUND(C5-D5,2) -> 0
A6: Interest: ledger (section INT) vs IS_Annual TOTAL | B6: 2023 | C6: =SUMIFS(Transactions!$Q$2:$Q$1092,Transactions!$J$2:$J$1092,"INT",Transactions!$AA$2:$AA$1092,2023,Transactions!$F$2:$F$1092,"Current",Transactions!$C$2:$C$1092,"<="&DATE(2026,9,30)) -> 41451.19 | D6: =IS_Annual_Enterprise!L27 -> 41451.19 | E6: =ROUND(C6-D6,2) -> 0
A7: Revenue: ledger (section REV) vs IS_Annual TOTAL | B7: 2024 | C7: =SUMIFS(Transactions!$Q$2:$Q$1092,Transactions!$J$2:$J$1092,"REV",Transactions!$AA$2:$AA$1092,2024,Transactions!$F$2:$F$1092,"Current",Transactions!$C$2:$C$1092,"<="&DATE(2026,9,30)) -> 429071.06 | D7: =IS_Annual_Enterprise!D28 -> 429071.06 | E7: =ROUND(C7-D7,2) -> 0
A8: Cost of production: ledger (section COP) vs IS_Annual TOTAL | B8: 2024 | C8: =SUMIFS(Transactions!$Q$2:$Q$1092,Transactions!$J$2:$J$1092,"COP",Transactions!$AA$2:$AA$1092,2024,Transactions!$F$2:$F$1092,"Current",Transactions!$C$2:$C$1092,"<="&DATE(2026,9,30)) -> 194297.69 | D8: =IS_Annual_Enterprise!F28 -> 194297.69 | E8: =ROUND(C8-D8,2) -> 0
A9: Interest: ledger (section INT) vs IS_Annual TOTAL | B9: 2024 | C9: =SUMIFS(Transactions!$Q$2:$Q$1092,Transactions!$J$2:$J$1092,"INT",Transactions!$AA$2:$AA$1092,2024,Transactions!$F$2:$F$1092,"Current",Transactions!$C$2:$C$1092,"<="&DATE(2026,9,30)) -> 41973.14 | D9: =IS_Annual_Enterprise!L28 -> 41973.14 | E9: =ROUND(C9-D9,2) -> 0
A10: Revenue: ledger (section REV) vs IS_Annual TOTAL | B10: 2025 | C10: =SUMIFS(Transactions!$Q$2:$Q$1092,Transactions!$J$2:$J$1092,"REV",Transactions!$AA$2:$AA$1092,2025,Transactions!$F$2:$F$1092,"Current",Transactions!$C$2:$C$1092,"<="&DATE(2026,9,30)) -> 443445.2 | D10: =IS_Annual_Enterprise!D29 -> 443445.2 | E10: =ROUND(C10-D10,2) -> 0
A11: Cost of production: ledger (section COP) vs IS_Annual TOTAL | B11: 2025 | C11: =SUMIFS(Transactions!$Q$2:$Q$1092,Transactions!$J$2:$J$1092,"COP",Transactions!$AA$2:$AA$1092,2025,Transactions!$F$2:$F$1092,"Current",Transactions!$C$2:$C$1092,"<="&DATE(2026,9,30)) -> 247894.11 | D11: =IS_Annual_Enterprise!F29 -> 247894.11 | E11: =ROUND(C11-D11,2) -> 0
A12: Interest: ledger (section INT) vs IS_Annual TOTAL | B12: 2025 | C12: =SUMIFS(Transactions!$Q$2:$Q$1092,Transactions!$J$2:$J$1092,"INT",Transactions!$AA$2:$AA$1092,2025,Transactions!$F$2:$F$1092,"Current",Transactions!$C$2:$C$1092,"<="&DATE(2026,9,30)) -> 44597.46 | D12: =IS_Annual_Enterprise!L29 -> 44597.46 | E12: =ROUND(C12-D12,2) -> 0
A13: Revenue: ledger (section REV) vs IS_Annual TOTAL | B13: 2026 | C13: =SUMIFS(Transactions!$Q$2:$Q$1092,Transactions!$J$2:$J$1092,"REV",Transactions!$AA$2:$AA$1092,2026,Transactions!$F$2:$F$1092,"Current",Transactions!$C$2:$C$1092,"<="&DATE(2026,9,30)) -> 234120.21 | D13: =IS_Annual_Enterprise!D30 -> 234120.21 | E13: =ROUND(C13-D13,2) -> 0
A14: Cost of production: ledger (section COP) vs IS_Annual TOTAL | B14: 2026 | C14: =SUMIFS(Transactions!$Q$2:$Q$1092,Transactions!$J$2:$J$1092,"COP",Transactions!$AA$2:$AA$1092,2026,Transactions!$F$2:$F$1092,"Current",Transactions!$C$2:$C$1092,"<="&DATE(2026,9,30)) -> 161688.09 | D14: =IS_Annual_Enterprise!F30 -> 161688.09 | E14: =ROUND(C14-D14,2) -> 0
A15: Interest: ledger (section INT) vs IS_Annual TOTAL | B15: 2026 | C15: =SUMIFS(Transactions!$Q$2:$Q$1092,Transactions!$J$2:$J$1092,"INT",Transactions!$AA$2:$AA$1092,2026,Transactions!$F$2:$F$1092,"Current",Transactions!$C$2:$C$1092,"<="&DATE(2026,9,30)) -> 34762.64 | D15: =IS_Annual_Enterprise!L30 -> 34762.64 | E15: =ROUND(C15-D15,2) -> 0
A16: Balance sheet: max |assets - liabilities - equity| across all month-ends | C16: =MAX(BS_Monthly!B38:AU38) -> 0 | D16: =MIN(BS_Monthly!B38:AU38) -> 0 | E16: =ROUND(MAX(ABS(C16),ABS(D16)),2) -> 0
A17: Cash: BS_Monthly cash at 9/30/2026 vs CF_Monthly ending cash | C17: =BS_Monthly!AU4 -> 28343.6 | D17: =CF_Monthly!AJ47 -> 28343.6 | E17: =ROUND(C17-D17,2) -> 0
A18: Cash: opening cash + SUM(ledger cash_effect) vs BS cash at 9/30/2026 | C18: =BS_Monthly!B4+SUMIFS(Transactions!$R$2:$R$1092,Transactions!$D$2:$D$1092,">="&DATE(2023,1,1)) -> 28343.6 | D18: =BS_Monthly!AU4 -> 28343.6 | E18: =ROUND(C18-D18,2) -> 0
A19: Accounts receivable: open AR invoices vs BS AR at 9/30/2026 (BS also includes small non-invoiced items) | C19: =SUM(AR_Invoices!J2:J108) -> 17457.23 | D19: =BS_Monthly!AU5 -> 17457.23 | E19: =ROUND(C19-D19,2) -> 0
A20: Debt: Loans principal at 9/30/2026 (term + line) vs BS term debt + operating line | C20: =SUM(Loans!Q2:Q7) -> 834842.73 | D20: =BS_Monthly!AU26+BS_Monthly!AU27+BS_Monthly!AU29+BS_Monthly!AU30+BS_Monthly!AU31+BS_Monthly!AU32 -> 834842.73 | E20: =ROUND(C20-D20,2) -> 0
A22: All checks pass | E22: =IF(SUMPRODUCT(ABS(E4:E20))<1,"PASS","REVIEW") -> PASS

Sheet AI_Insights
A1: AcreFlow financial-intelligence output for this account. Every figure is computed from the tables in this workbook.
A2: insight_id | B2: severity | C2: category | D2: title | E2: finding | F2: recommendation | G2: key_metrics | H2: source_tables
A3: INS-SAM-01 | B3: Positive | C3: Enterprise profitability | D3: Custom harvesting carries the whole business | E3: Custom combining & hauling earned $126,969 in 2025 (after its 85% share of combine depreciation, combine-loan interest, labor and repairs) on $265,688 of revenue - 60% of farm revenue. Total farm operating income was $42,941; without custom work the farm would have lost money in every year 2023-2025. | F3: Protect this enterprise: lock in 2027 client acres early, keep the combine reliable, and price fall corn at the KSU survey's upper range ($49-50/ac). | G3: {"custom_ni_2025": 126968.72, "custom_rev_share_2025": 0.599} | H3: income_statement_annual_by_enterprise
A4: INS-SAM-02 | B4: Warning | C4: Unprofitable crop | D4: Texas cotton has lost money every year, even with emergency aid | E4: Cotton profit per acre (including insurance and government payments, but no land charge): 2023 -$133, 2024 -$96, 2025 -$85; 2026 projects -$47. Break-even pool price ran $0.99-$1.39/lb against pool prices of $0.62-0.73. Custom costs alone ($210+/ac including stripping) consume most of the revenue. | F4: Compare against cash-renting the 100 ac (~$35-45/ac dryland Panhandle) or a crop-share lease; at the 2026 base price ($0.82) cotton only approaches break-even. | G4: {"cotton_profit_per_acre_2023": -133.39, "cotton_profit_per_acre_2024": -96.28, "cotton_profit_per_acre_2025": -85.34, "cotton_profit_per_acre_2026": -46.84} | H4: unit_economics_crops
A5: INS-SAM-03 | B5: Critical | C5: Upcoming cash shortage | D5: Profitable on paper, but the line can't carry next summer | E5: Year-end operating-line balances have ratcheted up: $92,000 (2023), $124,000 (2024), $175,000 (2025). The line reached its $250,000 limit in Aug-2026. The base-case 12-month forecast earns $72,263 of net farm income but still shows a cash shortfall of $44,510 in Jul-2027 with the line maxed - driven by Jan combine + Mar tractor payments, Dec prepaid inputs and slow cotton-pool cash. | F5: Before Jan-2027: term out ~$100k of the line over 5 years, renegotiate combine payment timing to Sep (after wheat custom season), and stop prepaying 2027 inputs in December. | G5: {"line_ye_2023": 92000.0, "line_ye_2025": 175000.0, "forecast_min_cash": -44509.53} | H5: operating_line_monthly; forecast_12_month; cash_forecast_13_week
A6: INS-SAM-04 | B6: Warning | C6: Liquidity & repayment capacity | D6: Working capital is eroding as the line funds term payments | E6: Year-end working capital went -$11,631, -$34,490, -$67,673 (2023-2025). Term debt coverage was FY2023 0.59, FY2024 1.19, FY2025 1.39, TTM Sep-2026 0.85 - below the 1.25 most lenders want in 2023 and TTM. | F6: Treat the TDCR as the binding constraint: no new term debt until it holds above 1.25; ask the lender to re-amortize the remaining combine and tractor balances together over 6 years. | G6: {"wc_FY2023": -11630.71, "wc_FY2024": -34489.54, "wc_FY2025": -67672.96, "tdcr_FY2023": 0.5947, "tdcr_FY2024": 1.1903, "tdcr_FY2025": 1.3923, "tdcr_TTM Sep-2026": 0.847} | H6: financial_ratios
A7: INS-SAM-05 | B7: Watch | C7: Equipment | D7: The combine is wearing out quickly | E7: The 2019 S770 logged about 469 separator hours in 2025 (~88% custom work) and has roughly 3,810 total hours. Combine repairs & pre-season service ran 2023 $20,101, 2024 $25,381, 2025 $38,495, 2026 $25,330 (2026 YTD), including the Aug-2025 rotor-gearbox/feeder-house failure ($18,420). The combine note ($45,115/yr) runs to Jan-2029. | F7: Run the repair-vs-replace model now: trading to a lower-hour S780 (~$520k) only pays if 2027+ custom acres hold above ~4,000. Otherwise budget ~$25k/yr in repairs and a backup-combine arrangement. | G7: {"combine_repairs": {"2023": 20101.0, "2024": 25380.56, "2025": 38495.04, "2026": 25330.4}, "separator_hours_2025": 469} | H7: assets; production_records; transactions
A8: INS-SAM-06 | B8: Warning | C8: Receivables | D8: One custom client owes for last fall's corn harvest | E8: Rudd Brothers Partnership owes $12,843 for Nov-2025 corn harvesting, now 354 days outstanding (324 past due; the acre count is disputed). Ostrander Farms pays in 91 days on average against net-30 terms. | F8: Require a 25% deposit or same-week payment from Rudd before fall-2026 work; reserve or write off the balance; add a 1.5%/month late fee to custom invoices. | G8: {"rudd_balance": 12843.25, "ostrander_avg_days": 91} | H8: ar_invoices
A9: INS-SAM-07 | B9: Watch | C9: Customer concentration | D9: 26% of custom revenue comes from one client | E9: Heartland Land & Cattle (CUS-SAM-101) provided $69,145 of $265,688 custom revenue in 2025 (26%). | F9: Sign a multi-year custom agreement with Heartland and add 1-2 smaller clients to diversify. | G9: {"top_client_share": 0.26} | H9: transactions; customers
A10: INS-SAM-08 | B10: Watch | C10: Commodity price risk | D10: Storing corn has cut both ways | E10: Holding 60% of the 2023 pivot corn crop past harvest ($4.65) and selling it in Mar-May 2024 ($4.25-4.30) cost about $5,744 versus harvest-time sale. In 2025 the same strategy gained (harvest $3.85, stored sales $4.20-4.30, average $4.12). Unpriced grain in the bin is a speculative position funded by the operating line. | F10: Store only with a positive carry captured by a forward or HTA contract (as done with the 4,000 bu soybean contract @ $10.45 for Nov-2026). | G10: {"corn23_avg_price": 4.41, "corn25_avg_price": 4.12} | H10: crop_seasons; transactions
A11: INS-SAM-09 | B11: Watch | C11: Input-cost sensitivity | D11: A 20% fertilizer increase would take 6% of 2025 profit | E11: Fertilizer spend was $28,491 in 2025; +20% (anhydrous was already +34% year over year in July 2026) costs $5,698, or 6% of 2025 net farm income ($101,633). | F11: Book fall-2026 anhydrous needs on the dip and use variable-rate N on the dryland corn ground. | G11: {"fertilizer_2025": 28491.2, "impact_plus_20pct": 5698.240000000001} | H11: transactions (5020); scenario_levers
A12: INS-SAM-10 | B12: Watch | C12: Government dependence | D12: Ad-hoc federal aid supplied a large share of recent profit | E12: Government program payments were $1,388 (2024), $25,850 (2025) and $22,429 (2026 YTD, mostly the Farmer Bridge Assistance payment). 2025's $25,850 equals 25% of that year's net farm income. | F12: Build budgets without ad-hoc programs (ECAP/FBA/SDRP); count only enrolled ARC/PLC with OBBBA reference prices. | G12: {"2024": 1388.0, "2025": 25850.04, "2026": 22429.0} | H12: transactions (4210)

Sheet Enterprises
A1: enterprise_id | B1: business_id | C1: enterprise_name | D1: enterprise_type | E1: parent_enterprise_id | F1: notes
A2: ENT-SAM-COT | B2: BIZ-SAM | C2: Texas dryland cotton (Carson Co.) | D2: Crop | F2: 96 planted ac, all field work contracted
A3: ENT-SAM-CORN | B3: BIZ-SAM | C3: Kansas corn | D3: Crop | F3: Pivot-irrigated and dryland
A4: ENT-SAM-SOY | B4: BIZ-SAM | C4: Kansas soybeans | D4: Crop | F4: Pivot-irrigated and dryland
A5: ENT-SAM-WHT | B5: BIZ-SAM | C5: Kansas hard red winter wheat | D5: Crop | F5: Dryland
A6: ENT-SAM-CUS | B6: BIZ-SAM | C6: Custom harvesting & grain hauling | D6: Service | F6: ~3,800-4,800 ac/yr for 8 neighbors
A7: ENT-SAM-OVH | B7: BIZ-SAM | C7: Kansas farm overhead & financing | D7: Overhead | F7: Shop, land loan, operating line, insurance

Sheet Land
A1: parcel_id | B1: business_id | C1: parcel_name | D1: acres | E1: use | F1: tenure | G1: enterprise_id
A2: LP-SAM-P1 | B2: BIZ-SAM | C2: KS-P1 center pivot | D2: 125 | E2: Irrigated corn/soy rotation | F2: Owned
A3: LP-SAM-D1 | B3: BIZ-SAM | C3: KS-D1 dryland | D3: 80 | E3: Wheat / soy / corn rotation | F3: Owned (2019 purchase)
A4: LP-SAM-D2 | B4: BIZ-SAM | C4: KS-D2 dryland | D4: 80 | E4: Wheat / soy / corn rotation | F4: Owned
A5: LP-SAM-HQ | B5: BIZ-SAM | C5: KS homestead, bins, shop, waterways | D5: 15 | E5: Headquarters | F5: Owned | G5: ENT-SAM-OVH
A6: LP-SAM-TX | B6: BIZ-SAM | C6: TX-C1 Carson Co. dryland | D6: 100 | E6: Cotton (96 planted + 4 turnrows) | F6: Owned (inherited 2017) | G6: ENT-SAM-COT

Sheet IS_Monthly
A1: Monthly income statement (accrual). Subtotals are formulas. Source: income_statement_monthly_summary / _detail.
A2: Line item | B2: 44957 | C2: 44985 | D2: 45016 | E2: 45046 | F2: 45077 | G2: 45107 | H2: 45138 | I2: 45169 | J2: 45199 | K2: 45230 | L2: 45260 | M2: 45291 | N2: 45322 | O2: 45351 | P2: 45382 | Q2: 45412 | R2: 45443 | S2: 45473 | T2: 45504 | U2: 45535 | V2: 45565 | W2: 45596 | X2: 45626 | Y2: 45657 | Z2: 45688 | AA2: 45716 | AB2: 45747 | AC2: 45777 | AD2: 45808 | AE2: 45838 | AF2: 45869 | AG2: 45900 | AH2: 45930 | AI2: 45961 | AJ2: 45991 | AK2: 46022 | AL2: 46053 | AM2: 46081 | AN2: 46112 | AO2: 46142 | AP2: 46173 | AQ2: 46203 | AR2: 46234 | AS2: 46265 | AT2: 46295
A3: Revenue | B3: 54644 | C3: 0 | D3: 0 | E3: 0 | F3: 0 | G3: 62275.88 | H3: 16027.87 | I3: 0 | J3: 32814 | K3: 157506.62 | L3: 27408.06 | M3: 23992.12 | N3: 8312.4 | O3: 3609.6 | P3: 38578.56 | Q3: 0 | R3: 27493.25 | S3: 44284.8 | T3: 52272.86 | U3: 0 | V3: 0 | W3: 134296.76 | X3: 85024 | Y3: 35198.83 | Z3: 47443.84 | AA3: 0 | AB3: 0 | AC3: 16691.04 | AD3: 0 | AE3: 51285.4 | AF3: 56376 | AG3: 6215 | AH3: 0 | AI3: 227216.68 | AJ3: 0 | AK3: 38217.24 | AL3: 17371.2 | AM3: 65177.38 | AN3: 11087.6 | AO3: 37073.36 | AP3: 0 | AQ3: 38039.51 | AR3: 33619.16 | AS3: 0 | AT3: 31752
A4: Cost of production | B4: 1344 | C4: 0 | D4: 23073.48 | E4: 62992.87 | F4: 17557.85 | G4: 20088.03 | H4: 25384.42 | I4: 13492.53 | J4: 23033.14 | K4: 22982.73 | L4: 19688.88 | M4: 3576.96 | N4: 1384.32 | O4: 0 | P4: 12626.47 | Q4: 10098.18 | R4: 42314.84 | S4: 22813.85 | T4: 22504.51 | U4: 8059.37 | V4: 19540.7 | W4: 27225.91 | X4: 21529.48 | Y4: 6200.06 | Z4: 1424.64 | AA4: 0 | AB4: 14026.88 | AC4: 48209.05 | AD4: 27808 | AE4: 23974.73 | AF4: 26395.34 | AG4: 27019.32 | AH4: 21109.15 | AI4: 31858.34 | AJ4: 18966.39 | AK4: 7102.27 | AL4: 1464.96 | AM4: 0 | AN4: 14095.04 | AO4: 40132.09 | AP4: 28050.68 | AQ4: 21452.28 | AR4: 21875.63 | AS4: 9704.72 | AT4: 24912.69
A5: Gross profit | B5: =B3-B4 -> 53300 | C5: =C3-C4 -> 0 | D5: =D3-D4 -> -23073.48 | E5: =E3-E4 -> -62992.87 | F5: =F3-F4 -> -17557.85 | G5: =G3-G4 -> 42187.85 | H5: =H3-H4 -> -9356.55 | I5: =I3-I4 -> -13492.53 | ... AT5: =AT3-AT4 -> 6839.31
A6: Gross margin % | B6: =IF(B3=0,0,B5/B3) -> 0.97540444 | C6: =IF(C3=0,0,C5/C3) -> 0 | D6: =IF(D3=0,0,D5/D3) -> 0 | E6: =IF(E3=0,0,E5/E3) -> 0 | F6: =IF(F3=0,0,F5/F3) -> 0 | G6: =IF(G3=0,0,G5/G3) -> 0.67743483 | H6: =IF(H3=0,0,H5/H3) -> -0.58376752 | I6: =IF(I3=0,0,I5/I3) -> 0 | ... AT6: =IF(AT3=0,0,AT5/AT3) -> 0.21539777
A7: Overhead / operating expenses | B7: 13265 | C7: 4387.28 | D7: 791.97 | E7: 1172.94 | F7: 700 | G7: 775.99 | H7: 688.03 | I7: 617.32 | J7: 728.81 | K7: 811.76 | L7: 774.48 | M7: 8122.02 | N7: 14191.72 | O7: 4527.16 | P7: 821.37 | Q7: 1164.19 | R7: 765.78 | S7: 707.41 | T7: 819.6 | U7: 687.89 | V7: 712.39 | W7: 851.23 | X7: 756.79 | Y7: 8388.47 | Z7: 19217.27 | AA7: 4601.49 | AB7: 776.79 | AC7: 1241.86 | AD7: 792.26 | AE7: 817.12 | AF7: 815.05 | AG7: 691.42 | AH7: 756.49 | AI7: 798.5 | AJ7: 739.97 | AK7: 8577.98 | AL7: 20275.3 | AM7: 4649.37 | AN7: 729.5 | AO7: 1199.26 | AP7: 674.3 | AQ7: 743.04 | AR7: 775.15 | AS7: 797.53 | AT7: 787.39
A8: EBITDA | B8: =B5-B7 -> 40035 | C8: =C5-C7 -> -4387.28 | D8: =D5-D7 -> -23865.45 | E8: =E5-E7 -> -64165.81 | F8: =F5-F7 -> -18257.85 | G8: =G5-G7 -> 41411.86 | H8: =H5-H7 -> -10044.58 | I8: =I5-I7 -> -14109.85 | ... AT8: =AT5-AT7 -> 6051.92
A9: Depreciation | B9: 5603.83 | C9: 5603.81 | D9: 5603.84 | E9: 5603.81 | F9: 5603.82 | G9: 5603.8 | H9: 5603.83 | I9: 5603.83 | J9: 5603.81 | K9: 5603.83 | L9: 5603.81 | M9: 5603.83 | N9: 5603.81 | O9: 5603.82 | P9: 5603.81 | Q9: 5603.83 | R9: 5603.82 | S9: 5603.81 | T9: 5603.83 | U9: 6132.99 | V9: 6132.99 | W9: 6132.98 | X9: 6132.99 | Y9: 6132.96 | Z9: 6133 | AA9: 6132.99 | AB9: 6414.23 | AC9: 6414.25 | AD9: 6414.23 | AE9: 6414.24 | AF9: 6414.22 | AG9: 6414.25 | AH9: 6414.22 | AI9: 6414.25 | AJ9: 6414.24 | AK9: 6414.22 | AL9: 6414.25 | AM9: 6414.23 | AN9: 6414.25 | AO9: 6414.22 | AP9: 6414.24 | AQ9: 6414.22 | AR9: 6414.25 | AS9: 6414.25 | AT9: 6414.22
A10: Operating profit | B10: =B8-B9 -> 34431.17 | C10: =C8-C9 -> -9991.09 | D10: =D8-D9 -> -29469.29 | E10: =E8-E9 -> -69769.62 | F10: =F8-F9 -> -23861.67 | G10: =G8-G9 -> 35808.06 | H10: =H8-H9 -> -15648.41 | I10: =I8-I9 -> -19713.68 | ... AT10: =AT8-AT9 -> -362.3
A11: Interest | B11: 13566.98 | C11: 501.3 | D11: 612.53 | E11: 707.77 | F11: 969.3 | G11: 1215.74 | H11: 1503.85 | I11: 1620.09 | J11: 1415.67 | K11: 1457.45 | L11: 965.67 | M11: 16914.84 | N11: 12266.85 | O11: 1125.05 | P11: 1194.91 | Q11: 921.99 | R11: 1039.45 | S11: 1083.51 | T11: 1325.64 | U11: 1628.4 | V11: 1802.54 | W11: 1682.9 | X11: 1299.42 | Y11: 16602.48 | Z11: 11002.53 | AA11: 1177.5 | AB11: 1490.29 | AC11: 1620.91 | AD11: 1698.62 | AE11: 1838.66 | AF11: 2125.37 | AG11: 2176.82 | AH11: 1863.28 | AI11: 1855.23 | AJ11: 1677.28 | AK11: 16070.97 | AL11: 9474.16 | AM11: 1479.91 | AN11: 13781.36 | AO11: 1413.34 | AP11: 1448.96 | AQ11: 1587.71 | AR11: 1863.79 | AS11: 1887.75 | AT11: 1825.66
A12: Gain (loss) on asset sales | B12: 0 | C12: 0 | D12: 0 | E12: 0 | F12: 0 | G12: 0 | H12: 0 | I12: 0 | J12: 0 | K12: 0 | L12: 0 | M12: 0 | N12: 0 | O12: 0 | P12: 0 | Q12: 0 | R12: 0 | S12: 0 | T12: 0 | U12: 0 | V12: 9500 | W12: 0 | X12: 0 | Y12: 0 | Z12: 0 | AA12: 0 | AB12: 8222.22 | AC12: 0 | AD12: 0 | AE12: 0 | AF12: 0 | AG12: 0 | AH12: 0 | AI12: 0 | AJ12: 0 | AK12: 0 | AL12: 0 | AM12: 0 | AN12: 0 | AO12: 0 | AP12: 0 | AQ12: 0 | AR12: 0 | AS12: 0 | AT12: 0
A13: Net income (operating basis) | B13: =B10-B11+B12 -> 20864.19 | C13: =C10-C11+C12 -> -10492.39 | D13: =D10-D11+D12 -> -30081.82 | E13: =E10-E11+E12 -> -70477.39 | F13: =F10-F11+F12 -> -24830.97 | G13: =G10-G11+G12 -> 34592.32 | H13: =H10-H11+H12 -> -17152.26 | I13: =I10-I11+I12 -> -21333.77 | ... AT13: =AT10-AT11+AT12 -> -2187.96
A14: Change in crop/hay/feed/supply inventories | B14: -52768 | C14: 0 | D14: 8960 | E14: 75815.37 | F14: 15166.5 | G14: 4825.45 | H14: 11064.21 | I14: 6302.54 | J14: -21149.28 | K14: -4454.59 | L14: -27277.05 | M14: -1552.5 | N14: -168.18 | O14: -1397.25 | P14: -30352.75 | Q14: 6729.75 | R14: 11229.12 | S14: 4203.2 | T14: 9073.27 | U14: 5443.48 | V14: 153.04 | W14: 4507.51 | X14: -31142.32 | Y14: 198.08 | Z14: -46029.76 | AA14: 0 | AB14: 8066.24 | AC14: 50374.24 | AD14: 25948.94 | AE14: 5773.28 | AF14: 12381.68 | AG14: 5726.72 | AH14: 169.6 | AI14: 24302.07 | AJ14: -29509.8 | AK14: 1488.54 | AL14: -14857.39 | AM14: -41992.68 | AN14: -1253.66 | AO14: -10385.14 | AP14: 32626.83 | AQ14: 476 | AR14: 10394.66 | AS14: 6557.61 | AT14: -21278.48
A15: Change in livestock values | B15: 0 | C15: 0 | D15: 0 | E15: 0 | F15: 0 | G15: 0 | H15: 0 | I15: 0 | J15: 0 | K15: 0 | L15: 0 | M15: 0 | N15: 0 | O15: 0 | P15: 0 | Q15: 0 | R15: 0 | S15: 0 | T15: 0 | U15: 0 | V15: 0 | W15: 0 | X15: 0 | Y15: 0 | Z15: 0 | AA15: 0 | AB15: 0 | AC15: 0 | AD15: 0 | AE15: 0 | AF15: 0 | AG15: 0 | AH15: 0 | AI15: 0 | AJ15: 0 | AK15: 0 | AL15: 0 | AM15: 0 | AN15: 0 | AO15: 0 | AP15: 0 | AQ15: 0 | AR15: 0 | AS15: 0 | AT15: 0
A16: Net farm income (accrual) | B16: =B13+B14+B15 -> -31903.81 | C16: =C13+C14+C15 -> -10492.39 | D16: =D13+D14+D15 -> -21121.82 | E16: =E13+E14+E15 -> 5337.98 | F16: =F13+F14+F15 -> -9664.47 | G16: =G13+G14+G15 -> 39417.77 | H16: =H13+H14+H15 -> -6088.05 | I16: =I13+I14+I15 -> -15031.23 | ... AT16: =AT13+AT14+AT15 -> -23466.44

Sheet IS_Annual_Enterprise
A1: Annual P&L by enterprise (2026 = YTD Sep). Enterprise rows include internal transfers at market; TOTAL excludes them.
A2: business_id | B2: period | C2: enterprise_id | D2: revenue | E2: internal_transfers_net | F2: cost_of_production | G2: gross_profit | H2: gross_margin_pct | I2: overhead | J2: ebitda | K2: depreciation | L2: interest | M2: gain_on_asset_sales | N2: net_income_operating_basis | O2: inventory_change | P2: livestock_value_change | Q2: net_farm_income_accrual
A3: BIZ-SAM | B3: 2023 | C3: ENT-SAM-CORN | D3: 75862.9 | E3: 0 | F3: 104128.88 | G3: -28265.98 | H3: -0.3726 | I3: 0 | J3: -28265.98 | K3: 18546.99 | L3: 0 | M3: 0 | N3: -46812.97 | O3: 69086.25 | P3: 0 | Q3: 22273.28
A4: BIZ-SAM | B4: 2023 | C4: ENT-SAM-COT | D4: 23992.12 | E4: 0 | F4: 36797.76 | G4: -12805.64 | H4: -0.5337 | I4: 431 | J4: -13236.64 | K4: 0 | L4: 0 | M4: 0 | N4: -13236.64 | O4: 0 | P4: 0 | Q4: -13236.64
A5: BIZ-SAM | B5: 2023 | C5: ENT-SAM-CUS | D5: 196886.41 | E5: 0 | F5: 66547.69 | G5: 130338.72 | H5: 0.662 | I5: 4540 | J5: 125798.72 | K5: 21035.26 | L5: 12838 | M5: 0 | N5: 91925.46 | O5: 0 | P5: 0 | Q5: 91925.46
A6: BIZ-SAM | B6: 2023 | C6: ENT-SAM-OVH | D6: 0 | E6: 0 | F6: 12366.52 | G6: -12366.52 | I6: 27864.6 | J6: -40231.12 | K6: 9120.84 | L6: 28613.19 | M6: 0 | N6: -77965.15 | O6: 0 | P6: 0 | Q6: -77965.15
A7: BIZ-SAM | B7: 2023 | C7: ENT-SAM-SOY | D7: 54644 | E7: 0 | F7: 0 | G7: 54644 | H7: 1 | I7: 0 | J7: 54644 | K7: 11623.04 | L7: 0 | M7: 0 | N7: 43020.96 | O7: -54112 | P7: 0 | Q7: -11091.04
A8: BIZ-SAM | B8: 2023 | C8: ENT-SAM-WHT | D8: 23283.12 | E8: 0 | F8: 13374.04 | G8: 9909.08 | H8: 0.4256 | I8: 0 | J8: 9909.08 | K8: 6919.72 | L8: 0 | M8: 0 | N8: 2989.36 | O8: -41.6 | P8: 0 | Q8: 2947.76
A9: BIZ-SAM | B9: 2024 | C9: ENT-SAM-CORN | D9: 74384.21 | E9: 0 | F9: 825.6 | G9: 73558.61 | H9: 0.9889 | I9: 0 | J9: 73558.61 | K9: 18943.87 | L9: 0 | M9: 1900 | N9: 56514.74 | O9: -69086.25 | P9: 0 | Q9: -12571.51
A10: BIZ-SAM | B10: 2024 | C10: ENT-SAM-COT | D10: 40196.43 | E10: 0 | F10: 44441.9 | G10: -4245.47 | H10: -0.1056 | I10: 443.93 | J10: -4689.4 | K10: 0 | L10: 0 | M10: 0 | N10: -4689.4 | O10: 0 | P10: 0 | Q10: -4689.4
A11: BIZ-SAM | B11: 2024 | C11: ENT-SAM-CUS | D11: 235377.78 | E11: 0 | F11: 75515.76 | G11: 159862.02 | H11: 0.6792 | I11: 4790 | J11: 155072.02 | K11: 23019.63 | L11: 12949.2 | M11: 5700 | N11: 124803.19 | O11: 0 | P11: 0 | Q11: 124803.19
A12: BIZ-SAM | B12: 2024 | C12: ENT-SAM-OVH | D12: 0 | E12: 0 | F12: 13424.82 | G12: -13424.82 | I12: 29160.07 | J12: -42584.89 | K12: 9120.83 | L12: 29023.94 | M12: 0 | N12: -80729.66 | O12: 0 | P12: 0 | Q12: -80729.66
A13: BIZ-SAM | B13: 2024 | C13: ENT-SAM-SOY | D13: 66902.4 | E13: 0 | F13: 47503.25 | G13: 19399.15 | H13: 0.29 | I13: 0 | J13: 19399.15 | K13: 11755.33 | L13: 0 | M13: 950 | N13: 8593.82 | O13: 39800 | P13: 0 | Q13: 48393.82
A14: BIZ-SAM | B14: 2024 | C14: ENT-SAM-WHT | D14: 12210.24 | E14: 0 | F14: 12586.36 | G14: -376.12 | H14: -0.0308 | I14: 0 | J14: -376.12 | K14: 7051.98 | L14: 0 | M14: 950 | N14: -6478.1 | O14: 7763.2 | P14: 0 | Q14: 1285.1
A15: BIZ-SAM | B15: 2025 | C15: ENT-SAM-CORN | D15: 39211.28 | E15: 0 | F15: 72982.28 | G15: -33771 | H15: -0.8613 | I15: 0 | J15: -33771 | K15: 20180.09 | L15: 0 | M15: 3700 | N15: -50251.09 | O15: 77891.35 | P15: 0 | Q15: 27640.26
A16: BIZ-SAM | B16: 2025 | C16: ENT-SAM-COT | D16: 49296.28 | E16: 0 | F16: 46409.95 | G16: 2886.33 | H16: 0.0586 | I16: 457.25 | J16: 2429.08 | K16: 0 | L16: 0 | M16: 0 | N16: 2429.08 | O16: 0 | P16: 0 | Q16: 2429.08
A17: BIZ-SAM | B17: 2025 | C17: ENT-SAM-CUS | D17: 265687.6 | E17: 0 | F17: 88849.14 | G17: 176838.46 | H17: 0.6656 | I17: 9005 | J17: 167833.46 | K17: 26967.87 | L17: 13896.87 | M17: 0 | N17: 126968.72 | O17: 0 | P17: 0 | Q17: 126968.72
A18: BIZ-SAM | B18: 2025 | C18: ENT-SAM-OVH | D18: 6215 | E18: 0 | F18: 13253.06 | G18: -7038.06 | H18: -1.1324 | I18: 30363.95 | J18: -37402.01 | K18: 9120.83 | L18: 30700.59 | M18: 0 | N18: -77223.43 | O18: 0 | P18: 0 | Q18: -77223.43
A19: BIZ-SAM | B19: 2025 | C19: ENT-SAM-SOY | D19: 62677.6 | E19: 0 | F19: 12280.8 | G19: 50396.8 | H19: 0.8041 | I19: 0 | J19: 50396.8 | K19: 12784.28 | L19: 0 | M19: 2466.67 | N19: 40079.19 | O19: -22412 | P19: 0 | Q19: 17667.19
A20: BIZ-SAM | B20: 2025 | C20: ENT-SAM-WHT | D20: 20357.44 | E20: 0 | F20: 14118.88 | G20: 6238.56 | H20: 0.3065 | I20: 0 | J20: 6238.56 | K20: 7355.27 | L20: 0 | M20: 2055.55 | N20: 938.84 | O20: 3212.4 | P20: 0 | Q20: 4151.24
A21: BIZ-SAM | B21: 2026 | C21: ENT-SAM-CORN | D21: 117118.74 | E21: 0 | F21: 25355.2 | G21: 91763.54 | H21: 0.7835 | I21: 0 | J21: 91763.54 | K21: 15237.16 | L21: 0 | M21: 0 | N21: 76526.38 | O21: -77887.3 | P21: 0 | Q21: -1360.92
A22: BIZ-SAM | B22: 2026 | C22: ENT-SAM-COT | D22: 11265.6 | E22: 0 | F22: 30800.4 | G22: -19534.8 | H22: -1.734 | I22: 0 | J22: -19534.8 | K22: 0 | L22: 0 | M22: 0 | N22: -19534.8 | O22: 30800.4 | P22: 0 | Q22: 11265.6
A23: BIZ-SAM | B23: 2026 | C23: ENT-SAM-CUS | D23: 60106.99 | E23: 0 | F23: 52364.37 | G23: 7742.62 | H23: 0.1288 | I23: 9545 | J23: -1802.38 | K23: 20401.42 | L23: 10275.41 | M23: 0 | N23: -32479.21 | O23: 0 | P23: 0 | Q23: -32479.21
A24: BIZ-SAM | B24: 2026 | C24: ENT-SAM-OVH | D24: 0 | E24: 0 | F24: 8675.31 | G24: -8675.31 | I24: 21085.84 | J24: -29761.15 | K24: 6840.63 | L24: 24487.23 | M24: 0 | N24: -61089.01 | O24: 0 | P24: 0 | Q24: -61089.01
A25: BIZ-SAM | B25: 2026 | C25: ENT-SAM-SOY | D25: 19841.6 | E25: 0 | F25: 35850.25 | G25: -16008.65 | H25: -0.8068 | I25: 0 | J25: -16008.65 | K25: 9714.76 | L25: 0 | M25: 0 | N25: -25723.41 | O25: 18462.25 | P25: 0 | Q25: -7261.16
A26: BIZ-SAM | B26: 2026 | C26: ENT-SAM-WHT | D26: 25787.28 | E26: 0 | F26: 8642.56 | G26: 17144.72 | H26: 0.6649 | I26: 0 | J26: 17144.72 | K26: 5534.16 | L26: 0 | M26: 0 | N26: 11610.56 | O26: -11087.6 | P26: 0 | Q26: 522.96
A27: BIZ-SAM | B27: 2023 | C27: TOTAL | D27: 374668.55 | E27: 0 | F27: 233214.89 | G27: 141453.66 | H27: 0.3775 | I27: 32835.6 | J27: 108618.06 | K27: 67245.85 | L27: 41451.19 | M27: 0 | N27: -78.98 | O27: 14932.65 | P27: 0 | Q27: 14853.67
A28: BIZ-SAM | B28: 2024 | C28: TOTAL | D28: 429071.06 | E28: 0 | F28: 194297.69 | G28: 234773.37 | H28: 0.5472 | I28: 34394 | J28: 200379.37 | K28: 69891.64 | L28: 41973.14 | M28: 9500 | N28: 98014.59 | O28: -21523.05 | P28: 0 | Q28: 76491.54
A29: BIZ-SAM | B29: 2025 | C29: TOTAL | D29: 443445.2 | E29: 0 | F29: 247894.11 | G29: 195551.09 | H29: 0.441 | I29: 39826.2 | J29: 155724.89 | K29: 76408.34 | L29: 44597.46 | M29: 8222.22 | N29: 42941.31 | O29: 58691.75 | P29: 0 | Q29: 101633.06
A30: BIZ-SAM | B30: 2026 | C30: TOTAL | D30: 234120.21 | E30: 0 | F30: 161688.09 | G30: 72432.12 | H30: 0.3094 | I30: 30630.84 | J30: 41801.28 | K30: 57728.13 | L30: 34762.64 | M30: 0 | N30: -50689.49 | O30: -39712.25 | P30: 0 | Q30: -90401.74

Sheet IS_Detail
A1: business_id | B1: month_end | C1: year | D1: enterprise_id | E1: section | F1: line_item | G1: account_code | H1: account_name | I1: amount
A2: BIZ-SAM | B2: 44957 | C2: 2023 | D2: ENT-SAM-CORN | E2: DEP | F2: Depreciation | G2: 7010 | H2: Depreciation | I2: -1545.59
A3: BIZ-SAM | B3: 44957 | C3: 2023 | D3: ENT-SAM-COT | E3: COP | F3: Contractors & custom hire | G3: 5050 | H3: Custom hire - field operations | I3: -1344
A4: BIZ-SAM | B4: 44957 | C4: 2023 | D4: ENT-SAM-COT | E4: INVCHG | F4: Change in inventories | G4: 7040 | H4: Change in crop, hay, feed & supply inventory | I4: 1344
A5: BIZ-SAM | B5: 44957 | C5: 2023 | D5: ENT-SAM-CUS | E5: OVH | F5: Insurance | G5: 6010 | H5: Insurance - property & liability | I5: -3900
A6: BIZ-SAM | B6: 44957 | C6: 2023 | D6: ENT-SAM-CUS | E6: OVH | F6: Professional & admin | G6: 6090 | H6: Dues, licenses & subscriptions | I6: -640
A7: BIZ-SAM | B7: 44957 | C7: 2023 | D7: ENT-SAM-CUS | E7: DEP | F7: Depreciation | G7: 7010 | H7: Depreciation | I7: -1752.94
A8: BIZ-SAM | B8: 44957 | C8: 2023 | D8: ENT-SAM-CUS | E8: INT | F8: Interest | G8: 7020 | H8: Interest - term debt | I8: -12838
A9: BIZ-SAM | B9: 44957 | C9: 2023 | D9: ENT-SAM-OVH | E9: OVH | F9: Insurance | G9: 6010 | H9: Insurance - property & liability | I9: -7880
A10: BIZ-SAM | B10: 44957 | C10: 2023 | D10: ENT-SAM-OVH | E10: OVH | F10: Utilities | G10: 6030 | H10: Utilities | I10: -395.26
A11: BIZ-SAM | B11: 44957 | C11: 2023 | D11: ENT-SAM-OVH | E11: OVH | F11: Vehicles | G11: 6050 | H11: Vehicle expense | I11: -284.74
A12: BIZ-SAM | B12: 44957 | C12: 2023 | D12: ENT-SAM-OVH | E12: OVH | F12: Professional & admin | G12: 6100 | H12: Office, phone & software | I12: -165
A13: BIZ-SAM | B13: 44957 | C13: 2023 | D13: ENT-SAM-OVH | E13: DEP | F13: Depreciation | G13: 7010 | H13: Depreciation | I13: -760.07
... A969: BIZ-SAM | B969: 46295 | C969: 2026 | D969: ENT-SAM-WHT | E969: DEP | F969: Depreciation | G969: 7010 | H969: Depreciation | I969: -614.92

Sheet BS_Monthly
A1: Month-end balance sheets. Inventories & livestock at market; land at cost. Totals and balance check are formulas (check row must be 0).
A2: Line item | B2: 44926 | C2: 44957 | D2: 44985 | E2: 45016 | F2: 45046 | G2: 45077 | H2: 45107 | I2: 45138 | J2: 45169 | K2: 45199 | L2: 45230 | M2: 45260 | N2: 45291 | O2: 45322 | P2: 45351 | Q2: 45382 | R2: 45412 | S2: 45443 | T2: 45473 | U2: 45504 | V2: 45535 | W2: 45565 | X2: 45596 | Y2: 45626 | Z2: 45657 | AA2: 45688 | AB2: 45716 | AC2: 45747 | AD2: 45777 | AE2: 45808 | AF2: 45838 | AG2: 45869 | AH2: 45900 | AI2: 45930 | AJ2: 45961 | AK2: 45991 | AL2: 46022 | AM2: 46053 | AN2: 46081 | AO2: 46112 | AP2: 46142 | AQ2: 46173 | AR2: 46203 | AS2: 46234 | AT2: 46265 | AU2: 46295
A3: ASSETS
A4: Cash | B4: 38650 | C4: 28757.98 | D4: 17890.12 | E4: 19009.7 | F4: 18481.95 | G4: 8639.32 | H4: 12293.77 | I4: 18396.44 | J4: 28907.7 | K4: 44674.04 | L4: 28239.45 | M4: 34702.95 | N4: 28484.64 | O4: 18585.91 | P4: 31138.38 | Q4: 28721.14 | R4: 13050.08 | S4: 33488.91 | T4: 10260.45 | U4: 19391.76 | V4: 28610.77 | W4: 28529.64 | X4: 28547.5 | Y4: 19624.15 | Z4: 28016.41 | AA4: 28279.41 | AB4: 28610.56 | AC4: 10619.69 | AD4: 30259.37 | AE4: 7827.54 | AF4: 13192.54 | AG4: 21496.6 | AH4: 28524.04 | AI4: 34337.55 | AJ4: 28015.45 | AK4: 30114.1 | AL4: 28482.26 | AM4: 28472.39 | AN4: 28861.47 | AO4: 22303.58 | AP4: 43716.98 | AQ4: 19174.14 | AR4: 14841.7 | AS4: 11353.71 | AT4: 27970.53 | AU4: 28343.6
A5: Accounts receivable | B5: 29956.8 | C5: 13480.56 | D5: 13480.56 | E5: 13480.56 | F5: 8987.04 | G5: 8987.04 | H5: 71262.92 | I5: 70982.55 | J5: 22693.97 | K5: 14536.56 | L5: 102989.32 | M5: 96530.32 | N5: 43671.65 | O5: 33062.65 | P5: 8680.08 | Q5: 8680.08 | R5: 5786.72 | S5: 5786.72 | T5: 50071.52 | U5: 87240.78 | V5: 28206.25 | W5: 2893.36 | X5: 66006.36 | Y5: 124970.21 | Z5: 77813.6 | AA5: 33100.14 | AB5: 13040.34 | AC5: 13040.34 | AD5: 8693.56 | AE5: 8693.56 | AF5: 59978.96 | AG5: 93576.38 | AH5: 28889.78 | AI5: 4346.78 | AJ5: 168244.6 | AK5: 131052.15 | AL5: 78353.79 | AM5: 34142.58 | AN5: 26685.19 | AO5: 26685.19 | AP5: 22071.21 | AQ5: 22071.21 | AR5: 60110.72 | AS5: 77564.22 | AT5: 35358.34 | AU5: 17457.23
A6: Prepaid expenses | B6: 33200 | C6: 33200 | D6: 33200 | E6: 33200 | F6: 0 | G6: 0 | H6: 0 | I6: 0 | J6: 0 | K6: 0 | L6: 0 | M6: 0 | N6: 8968.75 | O6: 8968.75 | P6: 8968.75 | Q6: 8968.75 | R6: 8968.75 | S6: 0 | T6: 0 | U6: 0 | V6: 0 | W6: 0 | X6: 0 | Y6: 0 | Z6: 28150 | AA6: 28150 | AB6: 28150 | AC6: 28150 | AD6: 0 | AE6: 0 | AF6: 0 | AG6: 0 | AH6: 0 | AI6: 0 | AJ6: 0 | AK6: 0 | AL6: 9406.25 | AM6: 9406.25 | AN6: 9406.25 | AO6: 9406.25 | AP6: 0 | AQ6: 0 | AR6: 0 | AS6: 0 | AT6: 0 | AU6: 0
A7: Crop & hay inventory | B7: 54112 | C7: 0 | D7: 0 | E7: 0 | F7: 0 | G7: 0 | H7: 7886.4 | I7: 7519.36 | J7: 7142.4 | K7: 6765.44 | L7: 71415 | M7: 70638.75 | N7: 69086.25 | O7: 67533.75 | P7: 66136.5 | Q7: 27622.63 | R7: 27816.7 | S7: 0 | T7: 8066.56 | U7: 8051.84 | V7: 8066.56 | W7: 8096 | X7: 47068.8 | Y7: 47256.32 | Z7: 47454.4 | AA7: 0 | AB7: 0 | AC7: 0 | AD7: 0 | AE7: 0 | AF7: 10197.2 | AG7: 10218.4 | AH7: 10239.6 | AI7: 10282 | AJ7: 101856.53 | AK7: 104454.41 | AL7: 105942.95 | AM7: 89620.6 | AN7: 47627.92 | AO7: 37250.9 | AP7: 4.28 | AQ7: 4.25 | AR7: 4937.63 | AS7: 4799.32 | AT7: 4669.65 | AU7: 4669.65
A8: Feed inventory | B8: 0 | C8: 0 | D8: 0 | E8: 0 | F8: 0 | G8: 0 | H8: 0 | I8: 0 | J8: 0 | K8: 0 | L8: 0 | M8: 0 | N8: 0 | O8: 0 | P8: 0 | Q8: 0 | R8: 0 | S8: 0 | T8: 0 | U8: 0 | V8: 0 | W8: 0 | X8: 0 | Y8: 0 | Z8: 0 | AA8: 0 | AB8: 0 | AC8: 0 | AD8: 0 | AE8: 0 | AF8: 0 | AG8: 0 | AH8: 0 | AI8: 0 | AJ8: 0 | AK8: 0 | AL8: 0 | AM8: 0 | AN8: 0 | AO8: 0 | AP8: 0 | AQ8: 0 | AR8: 0 | AS8: 0 | AT8: 0 | AU8: 0
A9: Investment in growing crops | B9: 4819.2 | C9: 6163.2 | D9: 6163.2 | E9: 15123.2 | F9: 90938.57 | G9: 106105.07 | H9: 103044.12 | I9: 114475.37 | J9: 121154.87 | K9: 100382.55 | L9: 31278.4 | M9: 4777.6 | N9: 4777.6 | O9: 6161.92 | P9: 6161.92 | Q9: 14323.04 | R9: 20858.72 | S9: 59904.54 | T9: 56041.18 | U9: 65129.17 | V9: 70557.93 | W9: 70681.53 | X9: 36216.24 | Y9: 4886.4 | Z9: 4886.4 | AA9: 6311.04 | AB9: 6311.04 | AC9: 14377.28 | AD9: 64751.52 | AE9: 90700.46 | AF9: 86276.54 | AG9: 98637.02 | AH9: 104342.54 | AI9: 104469.74 | AJ9: 37197.28 | AK9: 5089.6 | AL9: 5089.6 | AM9: 6554.56 | AN9: 6554.56 | AO9: 15677.92 | AP9: 42539.4 | AQ9: 75166.26 | AR9: 70708.88 | AS9: 81241.85 | AT9: 87929.13 | AU9: 66650.65
A10: Supplies, semen & packaged meat | B10: 0 | C10: 0 | D10: 0 | E10: 0 | F10: 0 | G10: 0 | H10: 0 | I10: 0 | J10: 0 | K10: 0 | L10: 0 | M10: 0 | N10: 0 | O10: 0 | P10: 0 | Q10: 0 | R10: 0 | S10: 0 | T10: 0 | U10: 0 | V10: 0 | W10: 0 | X10: 0 | Y10: 0 | Z10: 0 | AA10: 0 | AB10: 0 | AC10: 0 | AD10: 0 | AE10: 0 | AF10: 0 | AG10: 0 | AH10: 0 | AI10: 0 | AJ10: 0 | AK10: 0 | AL10: 0 | AM10: 0 | AN10: 0 | AO10: 0 | AP10: 0 | AQ10: 0 | AR10: 0 | AS10: 0 | AT10: 0 | AU10: 0
A11: Market livestock | B11: 0 | C11: 0 | D11: 0 | E11: 0 | F11: 0 | G11: 0 | H11: 0 | I11: 0 | J11: 0 | K11: 0 | L11: 0 | M11: 0 | N11: 0 | O11: 0 | P11: 0 | Q11: 0 | R11: 0 | S11: 0 | T11: 0 | U11: 0 | V11: 0 | W11: 0 | X11: 0 | Y11: 0 | Z11: 0 | AA11: 0 | AB11: 0 | AC11: 0 | AD11: 0 | AE11: 0 | AF11: 0 | AG11: 0 | AH11: 0 | AI11: 0 | AJ11: 0 | AK11: 0 | AL11: 0 | AM11: 0 | AN11: 0 | AO11: 0 | AP11: 0 | AQ11: 0 | AR11: 0 | AS11: 0 | AT11: 0 | AU11: 0
A12: Total current assets | B12: =B4+B5+B6+B7+B8+B9+B10+B11 -> 160738 | C12: =C4+C5+C6+C7+C8+C9+C10+C11 -> 81601.74 | D12: =D4+D5+D6+D7+D8+D9+D10+D11 -> 70733.88 | E12: =E4+E5+E6+E7+E8+E9+E10+E11 -> 80813.46 | F12: =F4+F5+F6+F7+F8+F9+F10+F11 -> 118407.56 | G12: =G4+G5+G6+G7+G8+G9+G10+G11 -> 123731.43 | H12: =H4+H5+H6+H7+H8+H9+H10+H11 -> 194487.21 | I12: =I4+I5+I6+I7+I8+I9+I10+I11 -> 211373.72 | ... AU12: =AU4+AU5+AU6+AU7+AU8+AU9+AU10+AU11 -> 117121.13
A13: Breeding livestock (market) | B13: 0 | C13: 0 | D13: 0 | E13: 0 | F13: 0 | G13: 0 | H13: 0 | I13: 0 | J13: 0 | K13: 0 | L13: 0 | M13: 0 | N13: 0 | O13: 0 | P13: 0 | Q13: 0 | R13: 0 | S13: 0 | T13: 0 | U13: 0 | V13: 0 | W13: 0 | X13: 0 | Y13: 0 | Z13: 0 | AA13: 0 | AB13: 0 | AC13: 0 | AD13: 0 | AE13: 0 | AF13: 0 | AG13: 0 | AH13: 0 | AI13: 0 | AJ13: 0 | AK13: 0 | AL13: 0 | AM13: 0 | AN13: 0 | AO13: 0 | AP13: 0 | AQ13: 0 | AR13: 0 | AS13: 0 | AT13: 0 | AU13: 0
A14: Machinery & equipment (net) | B14: 614260.28 | C14: 610356.52 | D14: 606452.78 | E14: 602549.02 | F14: 598645.28 | G14: 594741.52 | H14: 590837.79 | I14: 586934.03 | J14: 583030.28 | K14: 579126.53 | L14: 575222.77 | M14: 571319.03 | N14: 567415.27 | O14: 563511.53 | P14: 559607.77 | Q14: 555704.04 | R14: 551800.28 | S14: 547896.53 | T14: 543992.78 | U14: 540089.02 | V14: 536185.28 | W14: 532281.52 | X14: 528377.78 | Y14: 524474.02 | Z14: 520570.29 | AA14: 516666.53 | AB14: 512762.78 | AC14: 727300 | AD14: 723114.99 | AE14: 718930 | AF14: 714744.99 | AG14: 710560.01 | AH14: 706375 | AI14: 702190.01 | AJ14: 698005 | AK14: 693820 | AL14: 689635 | AM14: 685449.99 | AN14: 681265 | AO14: 677079.99 | AP14: 672895.01 | AQ14: 668710 | AR14: 664525.01 | AS14: 660340 | AT14: 656155 | AU14: 651970
A15: Vehicles (net) | B15: 58286.46 | C15: 57854.17 | D15: 57421.88 | E15: 56989.58 | F15: 56557.29 | G15: 56125 | H15: 55692.71 | I15: 55260.42 | J15: 54828.12 | K15: 54395.83 | L15: 53963.54 | M15: 53531.25 | N15: 53098.96 | O15: 52666.67 | P15: 52234.38 | Q15: 51802.08 | R15: 51369.79 | S15: 50937.5 | T15: 50505.21 | U15: 50072.92 | V15: 147611.45 | W15: 141650 | X15: 140688.54 | Y15: 139727.08 | Z15: 138765.63 | AA15: 137804.17 | AB15: 136842.71 | AC15: 135881.25 | AD15: 134919.79 | AE15: 133958.33 | AF15: 132996.88 | AG15: 132035.42 | AH15: 131073.95 | AI15: 130112.5 | AJ15: 129151.04 | AK15: 128189.58 | AL15: 127228.13 | AM15: 126266.67 | AN15: 125305.21 | AO15: 124343.75 | AP15: 123382.29 | AQ15: 122420.83 | AR15: 121459.38 | AS15: 120497.92 | AT15: 119536.45 | AU15: 118575
A16: Buildings & improvements (net) | B16: 272085.56 | C16: 270817.78 | D16: 269550 | E16: 268282.22 | F16: 267014.44 | G16: 265746.67 | H16: 264478.89 | I16: 263211.11 | J16: 261943.33 | K16: 260675.56 | L16: 259407.78 | M16: 258140 | N16: 256872.22 | O16: 255604.44 | P16: 254336.67 | Q16: 253068.89 | R16: 251801.11 | S16: 250533.33 | T16: 249265.56 | U16: 247997.78 | V16: 246730 | W16: 245462.22 | X16: 244194.44 | Y16: 242926.67 | Z16: 241658.89 | AA16: 240391.11 | AB16: 239123.33 | AC16: 237855.56 | AD16: 236587.78 | AE16: 235320 | AF16: 234052.22 | AG16: 232784.44 | AH16: 231516.67 | AI16: 230248.89 | AJ16: 228981.11 | AK16: 227713.33 | AL16: 226445.56 | AM16: 225177.78 | AN16: 223910 | AO16: 222642.22 | AP16: 221374.44 | AQ16: 220106.67 | AR16: 218838.89 | AS16: 217571.11 | AT16: 216303.33 | AU16: 215035.56
A17: Land (cost basis) | B17: 925000 | C17: 925000 | D17: 925000 | E17: 925000 | F17: 925000 | G17: 925000 | H17: 925000 | I17: 925000 | J17: 925000 | K17: 925000 | L17: 925000 | M17: 925000 | N17: 925000 | O17: 925000 | P17: 925000 | Q17: 925000 | R17: 925000 | S17: 925000 | T17: 925000 | U17: 925000 | V17: 925000 | W17: 925000 | X17: 925000 | Y17: 925000 | Z17: 925000 | AA17: 925000 | AB17: 925000 | AC17: 925000 | AD17: 925000 | AE17: 925000 | AF17: 925000 | AG17: 925000 | AH17: 925000 | AI17: 925000 | AJ17: 925000 | AK17: 925000 | AL17: 925000 | AM17: 925000 | AN17: 925000 | AO17: 925000 | AP17: 925000 | AQ17: 925000 | AR17: 925000 | AS17: 925000 | AT17: 925000 | AU17: 925000
A18: Total non-current assets | B18: =B13+B14+B15+B16+B17 -> 1869632.3 | C18: =C13+C14+C15+C16+C17 -> 1864028.5 | D18: =D13+D14+D15+D16+D17 -> 1858424.7 | E18: =E13+E14+E15+E16+E17 -> 1852820.8 | F18: =F13+F14+F15+F16+F17 -> 1847217 | G18: =G13+G14+G15+G16+G17 -> 1841613.2 | H18: =H13+H14+H15+H16+H17 -> 1836009.4 | I18: =I13+I14+I15+I16+I17 -> 1830405.6 | ... AU18: =AU13+AU14+AU15+AU16+AU17 -> 1910580.6
A19: TOTAL ASSETS | B19: =B12+B18 -> 2030370.3 | C19: =C12+C18 -> 1945630.2 | D19: =D12+D18 -> 1929158.5 | E19: =E12+E18 -> 1933634.3 | F19: =F12+F18 -> 1965624.6 | G19: =G12+G18 -> 1965344.6 | H19: =H12+H18 -> 2030496.6 | I19: =I12+I18 -> 2041779.3 | ... AU19: =AU12+AU18 -> 2027701.7
A20: LIABILITIES
A21: Accounts payable | B21: 3184.55 | C21: 1344 | D21: 0 | E21: 16373.48 | F21: 37355.37 | G21: 15166.5 | H21: 14650.69 | I21: 20725.5 | J21: 9537.5 | K21: 13168.28 | L21: 18454.48 | M21: 17473.33 | N21: 10296.96 | O21: 4961.28 | P21: 0 | Q21: 8476.47 | R21: 10098.18 | S21: 30684.57 | T21: 22247.96 | U21: 18816.24 | V21: 3995 | W21: 11746.8 | X21: 22324.18 | Y21: 17260.42 | Z21: 13112.06 | AA21: 7624.7 | AB21: 0 | AC21: 8126.88 | AD21: 20059.05 | AE21: 24988.94 | AF21: 29527.44 | AG21: 25064.01 | AH21: 22650 | AI21: 31077.6 | AJ21: 24405.3 | AK21: 17662.86 | AL21: 14302.27 | AM21: 8567.23 | AN21: 0 | AO21: 9145.04 | AP21: 30725.84 | AQ21: 31768.61 | AR21: 21712.86 | AS21: 17601.92 | AT21: 5170 | AU21: 15921.44
A22: Credit cards | B22: 0 | C22: 449.74 | D22: 554.28 | E22: 520.59 | F22: 935.65 | G22: 452.8 | H22: 2355.57 | I22: 420.28 | J22: 381.25 | K22: 4198.23 | L22: 557.46 | M22: 512.89 | N22: 450.11 | O22: 464.67 | P22: 507.66 | Q22: 549.84 | R22: 922.27 | S22: 484.23 | T22: 2451.19 | U22: 584.32 | V22: 435.56 | W22: 4445.64 | X22: 557.56 | Y22: 479.89 | Z22: 440.89 | AA22: 466.07 | AB22: 478.01 | AC22: 501.8 | AD22: 951.62 | AE22: 538.52 | AF22: 2705.92 | AG22: 522.06 | AH22: 414.23 | AI22: 4807.47 | AJ22: 497.5 | AK22: 462.26 | AL22: 454.24 | AM22: 484.05 | AN22: 403.75 | AO22: 482.54 | AP22: 957.95 | AQ22: 439.1 | AR22: 2790.93 | AS22: 509.31 | AT22: 534.06 | AU22: 5127.08
A23: Accrued property tax | B23: 3821.32 | C23: 3390.12 | D23: 3390.12 | E23: 3390.12 | F23: 3390.12 | G23: 0 | H23: 0 | I23: 0 | J23: 0 | K23: 0 | L23: 0 | M23: 0 | N23: 3821 | O23: 3390 | P23: 3390 | Q23: 3390 | R23: 3390 | S23: 0 | T23: 0 | U23: 0 | V23: 0 | W23: 0 | X23: 0 | Y23: 0 | Z23: 3952.58 | AA23: 3508.65 | AB23: 3508.65 | AC23: 3508.65 | AD23: 3508.65 | AE23: 0 | AF23: 0 | AG23: 0 | AH23: 0 | AI23: 0 | AJ23: 0 | AK23: 0 | AL23: 4088.7 | AM23: 3631.45 | AN23: 3631.45 | AO23: 3631.45 | AP23: 3631.45 | AQ23: 0 | AR23: 0 | AS23: 0 | AT23: 0 | AU23: 0
A24: Accrued payroll tax | B24: 0 | C24: 0 | D24: 0 | E24: 0 | F24: 0 | G24: 193.42 | H24: 290.16 | I24: 273.29 | J24: 207.31 | K24: 488.92 | L24: 366.26 | M24: 179.2 | N24: 0 | O24: 0 | P24: 0 | Q24: 0 | R24: 0 | S24: 215.27 | T24: 440.48 | U24: 298.31 | V24: 212.77 | W24: 296.86 | X24: 396.46 | Y24: 345.29 | Z24: 0 | AA24: 0 | AB24: 0 | AC24: 0 | AD24: 0 | AE24: 228.01 | AF24: 397.58 | AG24: 296.98 | AH24: 234.05 | AI24: 325.5 | AJ24: 602.82 | AK24: 105.43 | AL24: 0 | AM24: 0 | AN24: 0 | AO24: 0 | AP24: 0 | AQ24: 241.85 | AR24: 410.84 | AS24: 345.66 | AT24: 244.06 | AU24: 344.6
A25: Customer deposits (deferred revenue) | B25: 0 | C25: 0 | D25: 0 | E25: 0 | F25: 0 | G25: 0 | H25: 0 | I25: 0 | J25: 0 | K25: 0 | L25: 0 | M25: 0 | N25: 0 | O25: 0 | P25: 0 | Q25: 0 | R25: 0 | S25: 0 | T25: 0 | U25: 0 | V25: 0 | W25: 0 | X25: 0 | Y25: 0 | Z25: 0 | AA25: 0 | AB25: 0 | AC25: 0 | AD25: 0 | AE25: 0 | AF25: 0 | AG25: 0 | AH25: 0 | AI25: 0 | AJ25: 0 | AK25: 0 | AL25: 0 | AM25: 0 | AN25: 0 | AO25: 0 | AP25: 0 | AQ25: 0 | AR25: 0 | AS25: 0 | AT25: 0 | AU25: 0
A26: Operating line | B26: 70000 | C26: 59000 | D26: 59000 | E26: 73000 | F26: 86000 | G26: 126000 | H26: 158000 | I26: 176000 | J26: 170000 | K26: 170000 | L26: 113000 | M26: 113000 | N26: 92000 | O26: 139000 | P26: 139000 | Q26: 109000 | R26: 109000 | S26: 125000 | T26: 141000 | U26: 170000 | V26: 177000 | W26: 157000 | X26: 115000 | Y26: 115000 | Z26: 124000 | AA26: 113000 | AB26: 113000 | AC26: 155000 | AD26: 172000 | AE26: 185000 | AF26: 218000 | AG26: 246000 | AH26: 221000 | AI26: 221000 | AJ26: 203000 | AK26: 203000 | AL26: 175000 | AM26: 197000 | AN26: 146000 | AO26: 177000 | AP26: 177000 | AQ26: 192000 | AR26: 228000 | AS26: 245000 | AT26: 250000 | AU26: 221000
A27: Current portion of term debt | B27: 57410.83 | C27: 59021.68 | D27: 59051.06 | E27: 59080.53 | F27: 59110.09 | G27: 59139.75 | H27: 59169.51 | I27: 59199.37 | J27: 59229.32 | K27: 59259.37 | L27: 59289.52 | M27: 59319.76 | N27: 60051.53 | O27: 61741.03 | P27: 61771.57 | Q27: 61802.21 | R27: 61832.95 | S27: 61863.79 | T27: 61894.73 | U27: 61925.77 | V27: 78054.73 | W27: 78183.23 | X27: 78312.41 | Y27: 78442.29 | Z27: 79304.82 | AA27: 81176.45 | AB27: 81308.43 | AC27: 104224.27 | AD27: 104357.67 | AE27: 104491.79 | AF27: 104626.31 | AG27: 103916.78 | AH27: 103205.24 | AI27: 102491.68 | AJ27: 101776.09 | AK27: 101058.47 | AL27: 101102.6 | AM27: 102206.54 | AN27: 101482.8 | AO27: 102463.46 | AP27: 101735.61 | AQ27: 101005.7 | AR27: 100274.04 | AS27: 100385.08 | AT27: 100496.79 | AU27: 100609.17
A28: Total current liabilities | B28: =B21+B22+B23+B24+B25+B26+B27 -> 134416.7 | C28: =C21+C22+C23+C24+C25+C26+C27 -> 123205.54 | D28: =D21+D22+D23+D24+D25+D26+D27 -> 121995.46 | E28: =E21+E22+E23+E24+E25+E26+E27 -> 152364.72 | F28: =F21+F22+F23+F24+F25+F26+F27 -> 186791.23 | G28: =G21+G22+G23+G24+G25+G26+G27 -> 200952.47 | H28: =H21+H22+H23+H24+H25+H26+H27 -> 234465.93 | I28: =I21+I22+I23+I24+I25+I26+I27 -> 256618.44 | ... AU28: =AU21+AU22+AU23+AU24+AU25+AU26+AU27 -> 343002.29
A29: Land loans (non-current) | B29: 330323.13 | C29: 327715.84 | D29: 327658.15 | E29: 327600.14 | F29: 327541.8 | G29: 327483.14 | H29: 327424.13 | I29: 327364.79 | J29: 327305.12 | K29: 327245.1 | L29: 327184.74 | M29: 327124.04 | N29: 311191.39 | O29: 308035.18 | P29: 307964.95 | Q29: 307894.3 | R29: 307823.23 | S29: 307751.73 | T29: 307679.79 | U29: 307607.43 | V29: 303085.22 | W29: 302873.13 | X29: 302658.53 | Y29: 302441.39 | Z29: 285968.57 | AA29: 282037.92 | AB29: 281784.18 | AC29: 281988.98 | AD29: 281789.13 | AE29: 281587.06 | AF29: 281382.89 | AG29: 281562.03 | AH29: 281742.47 | AI29: 281924.22 | AJ29: 282107.3 | AK29: 282291.73 | AL29: 265940.94 | AM29: 262659.01 | AN29: 262835.43 | AO29: 260398.6 | AP29: 260574.72 | AQ29: 260752.24 | AR29: 260931.04 | AS29: 260753.69 | AT29: 260574.39 | AU29: 260393.14
A30: Equipment loans (non-current) | B30: 239108.19 | C30: 207996.68 | D30: 207960.06 | E30: 207923.24 | F30: 207886.22 | G30: 207848.98 | H30: 207811.53 | I30: 207773.87 | J30: 207735.99 | K30: 207697.9 | L30: 207659.59 | M30: 207621.07 | N30: 206718.24 | O30: 174462.89 | P30: 174423.11 | Q30: 174383.1 | R30: 174342.84 | S30: 174302.35 | T30: 174261.61 | U30: 174220.62 | V30: 234761.45 | W30: 233460.82 | X30: 232153 | Y30: 230837.95 | Z30: 228279.82 | AA30: 193554.7 | AB30: 192235.3 | AC30: 332646.59 | AD30: 331251.67 | AE30: 329848.8 | AF30: 328438.1 | AG30: 327467.83 | AH30: 326490.44 | AI30: 325505.87 | AJ30: 324514.06 | AK30: 323514.97 | AL30: 320746.52 | AM30: 284160.95 | AN30: 283138.74 | AO30: 260255.21 | AP30: 259214.02 | AQ30: 258165.21 | AR30: 257108.58 | AS30: 255693.55 | AT30: 254270.85 | AU30: 252840.42
A31: Vehicle loans (non-current) | B31: 30232.97 | C31: 29326.65 | D31: 28651.75 | E31: 27974.89 | F31: 27296.05 | G31: 26615.23 | H31: 25932.44 | I31: 25247.66 | J31: 24560.89 | K31: 23872.13 | L31: 23181.37 | M31: 22488.61 | N31: 21703.13 | O31: 20800.07 | P31: 20110.34 | Q31: 19418.66 | R31: 18725.05 | S31: 18029.49 | T31: 17331.97 | U31: 16632.51 | V31: 15700.6 | W31: 15000.46 | X31: 14298.94 | Y31: 13596.04 | Z31: 12822.36 | AA31: 11962.75 | AB31: 11267.01 | AC31: 10587.5 | AD31: 9890.56 | AE31: 9192.28 | AF31: 8492.67 | AG31: 7802.45 | AH31: 7109.12 | AI31: 6412.65 | AJ31: 5713.02 | AK31: 5010.21 | AL31: 4280.69 | AM31: 3528.87 | AN31: 2829.52 | AO31: 2105.8 | AP31: 1407.01 | AQ31: 704.99 | AR31: 0 | AS31: 0 | AT31: 0 | AU31: 0
A32: Other term debt (non-current) | B32: 0 | C32: 0 | D32: 0.01 | E32: 0 | F32: 0 | G32: 0 | H32: 0 | I32: 0 | J32: 0 | K32: 0 | L32: 0 | M32: -0.01 | N32: 0 | O32: 0 | P32: 0 | Q32: 0 | R32: 0 | S32: -0.01 | T32: 0 | U32: -0.01 | V32: 0 | W32: 0 | X32: 0 | Y32: 0 | Z32: 0 | AA32: 0 | AB32: 0 | AC32: 0 | AD32: 0 | AE32: 0 | AF32: 0 | AG32: 0.01 | AH32: 0 | AI32: -0.01 | AJ32: 0 | AK32: 0 | AL32: 0 | AM32: 0 | AN32: 0 | AO32: 0 | AP32: 0 | AQ32: 0 | AR32: 0 | AS32: 0 | AT32: 0 | AU32: 0
A33: TOTAL LIABILITIES | B33: =B28+B29+B30+B31+B32 -> 734080.99 | C33: =C28+C29+C30+C31+C32 -> 688244.71 | D33: =D28+D29+D30+D31+D32 -> 686265.43 | E33: =E28+E29+E30+E31+E32 -> 715862.99 | F33: =F28+F29+F30+F31+F32 -> 749515.3 | G33: =G28+G29+G30+G31+G32 -> 762899.82 | H33: =H28+H29+H30+H31+H32 -> 795634.03 | I33: =I28+I29+I30+I31+I32 -> 817004.76 | ... AU33: =AU28+AU29+AU30+AU31+AU32 -> 856235.85
A34: EQUITY
A35: Owner contributed capital | B35: 529000 | C35: 529000 | D35: 529000 | E35: 529000 | F35: 529000 | G35: 529000 | H35: 529000 | I35: 529000 | J35: 529000 | K35: 529000 | L35: 529000 | M35: 529000 | N35: 529000 | O35: 529000 | P35: 529000 | Q35: 529000 | R35: 529000 | S35: 529000 | T35: 529000 | U35: 529000 | V35: 529000 | W35: 529000 | X35: 529000 | Y35: 529000 | Z35: 529000 | AA35: 529000 | AB35: 529000 | AC35: 529000 | AD35: 529000 | AE35: 529000 | AF35: 529000 | AG35: 529000 | AH35: 529000 | AI35: 529000 | AJ35: 529000 | AK35: 529000 | AL35: 529000 | AM35: 529000 | AN35: 529000 | AO35: 529000 | AP35: 529000 | AQ35: 529000 | AR35: 529000 | AS35: 529000 | AT35: 529000 | AU35: 529000
A36: Retained earnings | B36: 767289.31 | C36: 728385.5 | D36: 713893.11 | E36: 688771.29 | F36: 687109.27 | G36: 673444.8 | H36: 705862.57 | I36: 695774.52 | J36: 676743.29 | K36: 650626.58 | L36: 768822.84 | M36: 737921.01 | N36: 722142.98 | O36: 689240.5 | P36: 676096.82 | Q36: 659976.07 | R36: 641317.63 | S36: 626216.11 | T36: 636895.53 | U36: 663888.08 | V36: 648722.91 | W36: 622587.33 | X36: 721398.58 | Y36: 741461.58 | Z36: 735434.52 | AA36: 693371.16 | AB36: 677259.18 | AC36: 666639.45 | AD36: 670518.66 | AE36: 655554.49 | AF36: 673868.42 | AG36: 702676.12 | AH36: 674116.03 | AI36: 638442.49 | AJ36: 844834.92 | AK36: 783327.24 | AL36: 780667.58 | AM36: 738852.72 | AN36: 745293.91 | AO36: 715907.7 | AP36: 686737.01 | AQ36: 678575.66 | AR36: 680193.92 | AS36: 689078.92 | AT36: 672632.28 | AU36: 642465.84
A37: TOTAL EQUITY | B37: =B35+B36 -> 1296289.3 | C37: =C35+C36 -> 1257385.5 | D37: =D35+D36 -> 1242893.1 | E37: =E35+E36 -> 1217771.3 | F37: =F35+F36 -> 1216109.3 | G37: =G35+G36 -> 1202444.8 | H37: =H35+H36 -> 1234862.6 | I37: =I35+I36 -> 1224774.5 | ... AU37: =AU35+AU36 -> 1171465.8
A38: Balance check (assets - liabilities - equity) | B38: =B19-B33-B37 -> 0 | C38: =C19-C33-C37 -> 0 | D38: =D19-D33-D37 -> 0 | E38: =E19-E33-E37 -> 0 | F38: =F19-F33-F37 -> 0 | G38: =G19-G33-G37 -> 0 | H38: =H19-H33-H37 -> 0 | I38: =I19-I33-I37 -> 0 | ... AU38: =AU19-AU33-AU37 -> 0
A39: memo: cumulative owner distributions since 1/2023 | B39: 0 | C39: 7000 | D39: 11000 | E39: 15000 | F39: 22000 | G39: 26000 | H39: 33000 | I39: 37000 | J39: 41000 | K39: 48000 | L39: 52000 | M39: 56000 | N39: 60000 | O39: 67600 | P39: 71700 | Q39: 75800 | R39: 83400 | S39: 87500 | T39: 95100 | U39: 99200 | V39: 103300 | W39: 110900 | X39: 115000 | Y39: 119100 | Z39: 123200 | AA39: 128900 | AB39: 133100 | AC39: 137300 | AD39: 143000 | AE39: 147200 | AF39: 152900 | AG39: 157100 | AH39: 161300 | AI39: 167000 | AJ39: 171200 | AK39: 175400 | AL39: 179600 | AM39: 186300 | AN39: 190500 | AO39: 194700 | AP39: 201400 | AQ39: 205600 | AR39: 212300 | AS39: 216500 | AT39: 220700 | AU39: 227400
A40: memo: land at market value | B40: 1695000 | C40: 1850000 | D40: 1850000 | E40: 1850000 | F40: 1850000 | G40: 1850000 | H40: 1850000 | I40: 1850000 | J40: 1850000 | K40: 1850000 | L40: 1850000 | M40: 1850000 | N40: 1850000 | O40: 1975000 | P40: 1975000 | Q40: 1975000 | R40: 1975000 | S40: 1975000 | T40: 1975000 | U40: 1975000 | V40: 1975000 | W40: 1975000 | X40: 1975000 | Y40: 1975000 | Z40: 1975000 | AA40: 2052500 | AB40: 2052500 | AC40: 2052500 | AD40: 2052500 | AE40: 2052500 | AF40: 2052500 | AG40: 2052500 | AH40: 2052500 | AI40: 2052500 | AJ40: 2052500 | AK40: 2052500 | AL40: 2052500 | AM40: 2085000 | AN40: 2085000 | AO40: 2085000 | AP40: 2085000 | AQ40: 2085000 | AR40: 2085000 | AS40: 2085000 | AT40: 2085000 | AU40: 2085000
...

Sheet CF_Monthly
A1: Monthly cash flow by class (signed: + inflow).
A2: business_id | B2: month_end | C2: beginning_cash | D2: Asset sale proceeds | E2: Chemical purchases | F2: Commodity-sale receipts | G2: Contractor payments | H2: Customer collections | I2: Debt payments - interest | J2: Debt payments - principal | K2: Equipment & capital purchases | L2: Feed purchases | M2: Fertilizer purchases | N2: Fuel | O2: Genetics payments | P2: Insurance | Q2: Insurance & government payments | R2: Lease receipts | S2: Livestock purchases | T2: Livestock-sale receipts | U2: Loan proceeds | V2: Operating line draws | W2: Operating line repayments | X2: Other operating payments | Y2: Other receipts | Z2: Owner contributions | AA2: Owner distributions | AB2: Payroll | AC2: Processing payments | AD2: Repairs | AE2: Seed purchases | AF2: Taxes | AG2: Taxes (owner estimated income tax) | AH2: Veterinary payments | AI2: net_cash_flow | AJ2: ending_cash | AK2: operating_line_balance
A3: BIZ-SAM | B3: 44957 | C3: 38650 | D3: 0 | E3: 0 | F3: 71120.24 | G3: 0 | H3: 0 | I3: -13566.98 | J3: -33014.27 | K3: 0 | L3: 0 | M3: 0 | N3: -3184.55 | O3: 0 | P3: -11780 | Q3: 0 | R3: 0 | S3: 0 | T3: 0 | U3: 0 | V3: 31000 | W3: -42000 | X3: -1035.26 | Y3: 0 | Z3: 0 | AA3: -4000 | AB3: 0 | AC3: 0 | AD3: 0 | AE3: 0 | AF3: -431.2 | AG3: -3000 | AH3: 0 | AI3: -9892.02 | AJ3: 28757.98 | AK3: 59000
A4: BIZ-SAM | B4: 44985 | C4: 28757.98 | D4: 0 | E4: 0 | F4: 0 | G4: -1344 | H4: 0 | I4: -501.3 | J4: -739.82 | K4: 0 | L4: 0 | M4: 0 | N4: 0 | O4: 0 | P4: 0 | Q4: 0 | R4: 0 | S4: 0 | T4: 0 | U4: 0 | V4: 0 | W4: 0 | X4: -4282.74 | Y4: 0 | Z4: 0 | AA4: -4000 | AB4: 0 | AC4: 0 | AD4: 0 | AE4: 0 | AF4: 0 | AG4: 0 | AH4: 0 | AI4: -10867.86 | AJ4: 17890.12 | AK4: 59000
A5: BIZ-SAM | B5: 45016 | C5: 17890.12 | D5: 0 | E5: 0 | F5: 0 | G5: 0 | H5: 0 | I5: -612.53 | J5: -742.23 | K5: 0 | L5: 0 | M5: 0 | N5: 0 | O5: 0 | P5: -6700 | Q5: 0 | R5: 0 | S5: 0 | T5: 0 | U5: 0 | V5: 14000 | W5: 0 | X5: -825.66 | Y5: 0 | Z5: 0 | AA5: -4000 | AB5: 0 | AC5: 0 | AD5: 0 | AE5: 0 | AF5: 0 | AG5: 0 | AH5: 0 | AI5: 1119.58 | AJ5: 19009.7 | AK5: 73000
A6: BIZ-SAM | B6: 45046 | C6: 19009.7 | D6: 0 | E6: -1120 | F6: 4493.52 | G6: -2304 | H6: 0 | I6: -707.77 | J6: -744.64 | K6: 0 | L6: 0 | M6: -4096 | N6: 0 | O6: 0 | P6: 0 | Q6: 0 | R6: 0 | S6: 0 | T6: 0 | U6: 0 | V6: 13000 | W6: 0 | X6: -757.88 | Y6: 0 | Z6: 0 | AA6: -4000 | AB6: 0 | AC6: 0 | AD6: -1290.98 | AE6: 0 | AF6: 0 | AG6: -3000 | AH6: 0 | AI6: -527.75 | AJ6: 18481.95 | AK6: 86000
A7: BIZ-SAM | B7: 45077 | C7: 18481.95 | D7: 0 | E7: -8299.5 | F7: 0 | G7: -864 | H7: 0 | I7: -969.3 | J7: -747.06 | K7: 0 | L7: 0 | M7: -19911.3 | N7: -2040.57 | O7: 0 | P7: 0 | Q7: 0 | R7: 0 | S7: 0 | T7: 0 | U7: 0 | V7: 40000 | W7: 0 | X7: -1182.85 | Y7: 0 | Z7: 0 | AA7: -4000 | AB7: -2197.93 | AC7: 0 | AD7: 0 | AE7: -6240 | AF7: -3390.12 | AG7: 0 | AH7: 0 | AI7: -9842.63 | AJ7: 8639.32 | AK7: 126000
A8: BIZ-SAM | B8: 45107 | C8: 8639.32 | D8: 0 | E8: -4990.5 | F8: 0 | G8: -2304 | H8: 0 | I8: -1215.74 | J8: -749.49 | K8: 0 | L8: 0 | M8: 0 | N8: 0 | O8: 0 | P8: 0 | Q8: 0 | R8: 0 | S8: 0 | T8: 0 | U8: 0 | V8: 32000 | W8: 0 | X8: -723.22 | Y8: 0 | Z8: 0 | AA8: -4000 | AB8: -3490.6 | AC8: 0 | AD8: 0 | AE8: -7872 | AF8: 0 | AG8: -3000 | AH8: 0 | AI8: 3654.45 | AJ8: 12293.77 | AK8: 158000
A9: BIZ-SAM | B9: 45138 | C9: 12293.77 | D9: 0 | E9: -3144 | F9: 16308.24 | G9: -864 | H9: 0 | I9: -1503.85 | J9: -751.92 | K9: 0 | L9: 0 | M9: 0 | N9: -660.44 | O9: 0 | P9: 0 | Q9: 0 | R9: 0 | S9: 0 | T9: 0 | U9: 0 | V9: 18000 | W9: 0 | X9: -7029.57 | Y9: 0 | Z9: 0 | AA9: -4000 | AB9: -3395.79 | AC9: 0 | AD9: -6856 | AE9: 0 | AF9: 0 | AG9: 0 | AH9: 0 | AI9: 6102.67 | AJ9: 18396.44 | AK9: 176000
A10: BIZ-SAM | B10: 45169 | C10: 18396.44 | D10: 0 | E10: -3500 | F10: 0 | G10: 0 | H10: 48288.58 | I10: -1620.09 | J10: -754.37 | K10: 0 | L10: 0 | M10: 0 | N10: -9294.25 | O10: 0 | P10: -1392 | Q10: 0 | R10: 0 | S10: 0 | T10: 0 | U10: 0 | V10: 14000 | W10: -20000 | X10: -8587.6 | Y10: 0 | Z10: 0 | AA10: -4000 | AB10: -2629.01 | AC10: 0 | AD10: 0 | AE10: 0 | AF10: 0 | AG10: 0 | AH10: 0 | AI10: 10511.26 | AJ10: 28907.7 | AK10: 170000
A11: BIZ-SAM | B11: 45199 | C11: 28907.7 | D11: 0 | E11: 0 | F11: 27942.4 | G11: -120 | H11: 8157.41 | I11: -1415.67 | J11: -756.82 | K11: 0 | L11: 0 | M11: 0 | N11: 0 | O11: 0 | P11: 0 | Q11: 4871.6 | R11: 0 | S11: 0 | T11: 0 | U11: 0 | V11: 0 | W11: 0 | X11: -5899.33 | Y11: 0 | Z11: 0 | AA11: -4000 | AB11: -5763.25 | AC11: 0 | AD11: -4250 | AE11: 0 | AF11: 0 | AG11: -3000 | AH11: 0 | AI11: 15766.34 | AJ11: 44674.04 | AK11: 170000
A12: BIZ-SAM | B12: 45230 | C12: 44674.04 | D12: 0 | E12: 0 | F12: 59010.82 | G12: 0 | H12: 10043.04 | I12: -1457.45 | J12: -759.28 | K12: 0 | L12: 0 | M12: 0 | N12: -973.28 | O12: 0 | P12: 0 | Q12: 0 | R12: 0 | S12: 0 | T12: 0 | U12: 0 | V12: 0 | W12: -57000 | X12: -4452.53 | Y12: 0 | Z12: 0 | AA12: -4000 | AB12: -4650.91 | AC12: 0 | AD12: -12195 | AE12: 0 | AF12: 0 | AG12: 0 | AH12: 0 | AI12: -16434.59 | AJ12: 28239.45 | AK12: 113000
A13: BIZ-SAM | B13: 45260 | C13: 28239.45 | D13: 0 | E13: 0 | F13: 0 | G13: 0 | H13: 33867.06 | I13: -965.67 | J13: -761.75 | K13: 0 | L13: 0 | M13: -1976 | N13: -9751.7 | O13: 0 | P13: 0 | Q13: 0 | R13: 0 | S13: 0 | T13: 0 | U13: 0 | V13: 0 | W13: 0 | X13: -819.05 | Y13: 0 | Z13: 0 | AA13: -4000 | AB13: -2402.61 | AC13: 0 | AD13: -4430.78 | AE13: -2296 | AF13: 0 | AG13: 0 | AH13: 0 | AI13: 6463.5 | AJ13: 34702.95 | AK13: 113000
A14: BIZ-SAM | B14: 45291 | C14: 34702.95 | D14: 0 | E14: 0 | F14: 0 | G14: 0 | H14: 76850.79 | I14: -16914.84 | J14: -16889.18 | K14: 0 | L14: 0 | M14: 0 | N14: -8762.09 | O14: 0 | P14: 0 | Q14: 0 | R14: 0 | S14: 0 | T14: 0 | U14: 0 | V14: 22000 | W14: -43000 | X14: -973.8 | Y14: 0 | Z14: 0 | AA14: -4000 | AB14: -179.2 | AC14: 0 | AD14: -1991.24 | AE14: -8968.75 | AF14: -3390 | AG14: 0 | AH14: 0 | AI14: -6218.31 | AJ14: 28484.64 | AK14: 92000
... A47: BIZ-SAM | B47: 46295 | C47: 27970.53 | D47: 0 | E47: 0 | F47: 31752 | G47: -130.8 | H47: 17901.11 | I47: -1825.66 | J47: -1499.3 | K47: 0 | L47: 0 | M47: 0 | N47: 0 | O47: 0 | P47: 0 | Q47: 0 | R47: 0 | S47: 0 | T47: 0 | U47: 0 | V47: 0 | W47: -29000 | X47: -5964.37 | Y47: 0 | Z47: 0 | AA47: -4200 | AB47: -4159.91 | AC47: 0 | AD47: 0 | AE47: 0 | AF47: 0 | AG47: -2500 | AH47: 0 | AI47: 373.07 | AJ47: 28343.6 | AK47: 221000

Sheet Ratios
